<?xml version="1.0" encoding="utf-8" ?>

<robot name="pushbot">
  <!-- Links -->
  <link name="base">
    <visual>
      <origin rpy="0 1.57079633 0" xyz="0 0 0"/>
      <geometry>
	<cylinder length="0.07" radius="0.1"/>
      </geometry>
    </visual>
    <collision>
      <origin rpy="0 1.57079633 0" xyz="0 0 0"/>
      <geometry>
	<cylinder length="0.07" radius="0.1"/>
      </geometry>
    </collision>
    <inertial>
      <origin rpy="0 1.57079633 0" xyz="0 0 0"/>
      <mass value="1"/>
      <inertia ixx="0.001" ixy= "0.0" ixz="0.0" iyy="0.001" iyz="0.0" izz="0.001"/>
    </inertial>
  </link>
  
  <link name="arm">
    <visual>
      <origin rpy="0 0 0" xyz="0 0 0.5"/>
      <geometry>
	<cylinder length="1.0" radius="0.05"/>
      </geometry>
    </visual>
    <collision>
      <origin rpy="0 0 0" xyz="0 0 0.5"/>      
      <geometry>
	<cylinder length="1.0" radius="0.05"/>
      </geometry>
    </collision>
    <inertial>
      <origin rpy="0 0 0" xyz="0 0 0.5"/>
      <mass value="1"/>
      <inertia ixx="0.001" ixy= "0.0" ixz="0.0" iyy="0.001" iyz="0.0" izz="0.001"/>
    </inertial>
  </link>

  <link name="ee_slider">
    <visual>
      <origin rpy="1.57079633 0 0" xyz="0 0 0"/>
      <geometry>
	<box size="0.05 0.05 0.3"/>
      </geometry>
    </visual>
  </link>
  
  <link name="end_effector">
    <visual>
      <geometry>
	<sphere radius="0.075"/>
      </geometry>
    </visual>
    <collision>
      <geometry>
	<sphere radius="0.075"/>
      </geometry>
    </collision>
    <inertial>
      <origin rpy="0 0 0" xyz="0 0 0"/>
      <mass value="0.01"/>
      <inertia ixx="0.001" ixy= "0.0" ixz="0.0" iyy="0.001" iyz="0.0" izz="0.001"/>
    </inertial>
  </link>

  <!-- Joints -->
  <joint name="base_joint" type="revolute">
    <parent link="base"/>
    <child link="arm"/>
    <origin xyz="0 0 0" rpy="0 0 0" />
    <axis xyz="1 0 0"/>
  </joint>

  <joint name="ee_slider_joint" type="fixed">
    <parent link="arm"/>
    <child link="ee_slider"/>
    <origin xyz="0 0 1.0" rpy="0 0 0" />
  </joint>
  
  <joint name="push_joint" type="prismatic">
    <parent link="arm"/>
    <child link="end_effector"/>
    <origin xyz="0 0 1.0" rpy="0 0 0" />
    <axis xyz="0 1 0"/>
  </joint>

  <!-- Transmissions -->
  <transmission name="base_transmission">
    <type>transmission_interface/SimpleTransmission</type>
    <joint name="base_joint">
      <hardwareInterface>EffortJointInterface</hardwareInterface>
    </joint>
    <actuator name="base_motor">
      <hardwareInterface>EffortJointInterface</hardwareInterface>
    </actuator>
  </transmission>

  <transmission name="push_transmission">
    <type>transmission_interface/SimpleTransmission</type>
    <joint name="push_joint">
      <hardwareInterface>EffortJointInterface</hardwareInterface>
    </joint>
    <actuator name="push_motor">
      <hardwareInterface>EffortJointInterface</hardwareInterface>
    </actuator>
  </transmission>
  
</robot>
