<?xml version="1.0" encoding="utf-8" ?>

<robot name="pushbot">
  <link name="base">
    <visual>
      <geometry>
	<box size="0.1 0.1 0.1"/>
      </geometry>
    </visual>
    <collision>
      <geometry>
	<box size="0.1 0.1 0.1"/>
      </geometry>
    </collision>
    <inertial>
      <origin rpy="0 0 0" xyz="0 0 0"/>
      <mass value="1"/>
      <inertia ixx="0.0" ixy= "0.0" ixz="0.0" iyy="0.0" iyz="0.0" izz="0.0"/>
    </inertial>
  </link>
  
  <link name="arm">
    <visual>
      <geometry>
	<box size="0.05 0.16 0.05"/>
      </geometry>
    </visual>
    <collision>
      <geometry>
	<box size="0.05 0.16 0.05"/>
      </geometry>
    </collision>
    <inertial>
      <origin rpy="0 0 0" xyz="0 0 0"/>
      <mass value="1"/>
      <inertia ixx="0.0" ixy= "0.0" ixz="0.0" iyy="0.0" iyz="0.0" izz="0.0"/>
    </inertial>
  </link>

  <link name="end_effector">
    <visual>
      <geometry>
	<sphere radius="0.005"/>
      </geometry>
    </visual>
    <collision>
      <geometry>
	<sphere radius="0.005"/>
      </geometry>
    </collision>
    <inertial>
      <origin rpy="0 0 0" xyz="0 0 0"/>
      <mass value="0.01"/>
      <inertia ixx="0.0" ixy= "0.0" ixz="0.0" iyy="0.0" iyz="0.0" izz="0.0"/>
    </inertial>
  </link>

  <joint name="base_joint" type="revolute">
    <parent link="base"/>
    <child link="arm"/>
    <origin xyz="0 0 0" rpy="0 0 0" />
    <axis xyz="1 0 0"/>
  </joint>

  <joint name="push_joint" type="prismatic">
    <parent link="arm"/>
    <child link="end_effector"/>
    <origin xyz="0 0.16 0" rpy="0 0 0" />
    <axis xyz="0 1 0"/>
  </joint>
</robot>
